Workbook
Name _Toc170362663: 'CMI Staff Exp Reimb POLICY'!$A$6
Name _Toc170362664: 'CMI Staff Exp Reimb POLICY'!$A$14
Name _Toc170363025: 'CMI Staff Exp Reimb POLICY'!$A$30
Name _Toc170363026: 'CMI Staff Exp Reimb POLICY'!$A$34
Name _Toc170363027: 'CMI Staff Exp Reimb POLICY'!$A$39
Name _Toc170363028: 'CMI Staff Exp Reimb POLICY'!$A$42
Name _Toc170363029: 'CMI Staff Exp Reimb POLICY'!$A$45
Name _Toc170363030: 'CMI Staff Exp Reimb POLICY'!$A$53
Name _Toc170363031: 'CMI Staff Exp Reimb POLICY'!$A$55
Name _Toc170363032: 'CMI Staff Exp Reimb POLICY'!$A$67
Name _Toc170363033: 'CMI Staff Exp Reimb POLICY'!$A$69
Name DR_LAST_REFRESH_ALL: 25568.7916666667

Sheet Exp Reimb Form
N2: CHILD MIND INSTITUTE / CHILD MIND MEDICAL PRACTICE NY / CHILD MIND MEDICAL PRACTICE CA - EXPENSE REIMBURSEMENT FORM
E3: This form is to be used by CMI employees to request reimbursement for business expenses or to clear outstanding cash advances. CMI will not reimburse requests for expenses that are deemed nonpermissable/nonreimbursable by the organization. For guidance, refer to the Expense Reimbursement Policy located on the Finance Yammer page.
A7: PAYEE INFORMATION
A8: 1. PAYEE'S NAME
A10: 2. HOME ADDRESS
A14: EXPENSE / ACCOUNT DETAILS
A15: 3. DATE | B15: 4. EXPENSE TYPE | D15: 5. AMOUNT | E15: 6. BUDGET CODING
E16: SELECT FROM DROPDOWN MENU ↓ | F16: Entity | G16: SELECT FROM DROPDOWN MENU ↓ | H16: GL Account | I16: SELECT FROM DROPDOWN MENU ↓ | J16: Department | K16: SELECT FROM DROPDOWN MENU ↓ | L16: Project | M16: SELECT FROM DROPDOWN MENU ↓ | N16: Grant | O16: SELECT FROM DROPDOWN MENU ↓ | P16: Clinician
F17: =IF(ISNA(VLOOKUP($E17,'Budget Coding Reference Alph'!K:L,2,FALSE))," ",VLOOKUP($E17,'Budget Coding Reference Alph'!K:L,2,FALSE)) | H17: =IF(ISNA(VLOOKUP($G17,'Budget Coding Reference Alph'!C:D,2,FALSE))," ",VLOOKUP($G17,'Budget Coding Reference Alph'!C:D,2,FALSE)) | J17: =IF(ISNA(VLOOKUP($I17,'Budget Coding Reference Alph'!A:B,2,FALSE))," ",VLOOKUP($I17,'Budget Coding Reference Alph'!A:B,2,FALSE)) | L17: =IF(ISNA(VLOOKUP($K17,'Budget Coding Reference Alph'!E:F,2,FALSE))," ",VLOOKUP($K17,'Budget Coding Reference Alph'!E:F,2,FALSE)) | N17: =IF(ISNA(VLOOKUP($M17,'Budget Coding Reference Alph'!G:H,2,FALSE))," ",VLOOKUP($M17,'Budget Coding Reference Alph'!G:H,2,FALSE)) | P17: =IF(ISNA(VLOOKUP($O17,'Budget Coding Reference Alph'!I:J,2,FALSE))," ",VLOOKUP($O17,'Budget Coding Reference Alph'!I:J,2,FALSE))
F18: =IF(ISNA(VLOOKUP($E18,'Budget Coding Reference Alph'!K:L,2,FALSE))," ",VLOOKUP($E18,'Budget Coding Reference Alph'!K:L,2,FALSE)) | H18: =IF(ISNA(VLOOKUP($G18,'Budget Coding Reference Alph'!C:D,2,FALSE))," ",VLOOKUP($G18,'Budget Coding Reference Alph'!C:D,2,FALSE)) | J18: =IF(ISNA(VLOOKUP($I18,'Budget Coding Reference Alph'!A:B,2,FALSE))," ",VLOOKUP($I18,'Budget Coding Reference Alph'!A:B,2,FALSE)) | L18: =IF(ISNA(VLOOKUP($K18,'Budget Coding Reference Alph'!E:F,2,FALSE))," ",VLOOKUP($K18,'Budget Coding Reference Alph'!E:F,2,FALSE)) | N18: =IF(ISNA(VLOOKUP($M18,'Budget Coding Reference Alph'!G:H,2,FALSE))," ",VLOOKUP($M18,'Budget Coding Reference Alph'!G:H,2,FALSE)) | P18: =IF(ISNA(VLOOKUP($O18,'Budget Coding Reference Alph'!I:J,2,FALSE))," ",VLOOKUP($O18,'Budget Coding Reference Alph'!I:J,2,FALSE))
A19: TOTAL EXPENSES: | C19: 10a | D19: =SUM(D17:D18) -> 0
A20: LESS CASH ADVANCE: * | C20: 10b | E20: *Cash Advance: Refers only to any preapproved and distributed cash advance
A21: EXPENSES NET OF ADVANCES: (10a - 10b = 10c) | C21: 10c | D21: =D19-D20 -> 0 | E21: If amount in 10c is less than zero, please attach a check payable to Child Mind Institute.
A22: 7. TOTAL AMOUNT OF REIMBURSEMENT (in words)
A24: 8. DESCRIPTION AND BUSINESS PURPOSE OF EXPENSE(S)
A28: 9. SIGNATURES / APPROVALS | D28: I, the Payee, certify that the charges reported here are correct and that I am not claiming reimbursement from other sources for the same.
A29: SIGNATURE OF PAYEE | E29: EMAIL ADDRESS OF PAYEE | H29: TEL. NUMBER | K29: DATE
A32: NAME OF APPROVER | E32: SIGNATURE OF APPROVER | H32: TEL. NUMBER | K32: DATE
A35: NAME OF APPROVER #2 (if applicable) | E35: SIGNATURE OF APPROVER #2 | H35: TEL. NUMBER | K35: DATE
A38: PAYEE AUTHORIZING ANOTHER PERSON TO PICK UP REIMBURSEMENT (Payee's Signature) | E38: NAME OF PERSON TO PICK UP REIMBURSEMENT | H38: SIGNATURE OF PERSON TO PICK UP REIMBURSEMENT

Sheet Budget Coding Reference Alph
A1: Intacct Dept Name | B1: Intacct Dept ID | C1: Intacct Name | D1: Intacct Natural | E1: Intacct Project Name | F1: Intacct Project ID | G1: Intacct ID Grant | H1: Intacct Location Name | I1: Intacct ID | J1: Intacct Location Name | K1: Entity or Fund name | L1: Entity or Fund ID
A2: CAMHI | B2: 810 | C2: Books and Periodical Subscriptions | D2: 65035 | E2: Default (Non-Project Specific) | F2: 9999 | G2: Default | H2: 9999999 | I2: Default (Non-Clinician Specific) | J2: 99999999 | K2: CMI Unrestricted | L2: 10-UNR
A3: Clinical Administration | B3: 170 | C3: Business Registration Fees | D3: 65050 | E3: Strategic Planning | F3: 1020 | G3: Anonymous $5M Donation (Meeting the Moment) September 2022 | H3: ANO1001 | I3: Alexander, Kimberly Ann | J3: Alexander, Kimberly Ann | K3: NY PLLC Unrestricted | L3: 20-UNR
A4: Clinical Centers - ADHD Clinical Center | B4: 410 | C4: C&C - Alcohol | D4: 69540 | E4: Fort Health (Telehealth) | F4: 1040 | G4: ASF - Wong Undergraduate Grant 2023 | H4: ASF1001 | I4: Allerhand, Lauren | J4: Allerhand, Lauren | K4: CA PC Unrestricted | L4: 30-UNR
A5: Clinical Centers - Anxiety Clinical Center | B5: 420 | C5: C&C - Audio Visual Rental | D5: 69530 | E5: Wellness (HR) | F5: 1055 | G5: BAR - Barclays - $150K Donation 9/18/20 | H5: BAR1001 | I5: Anderson, David | J5: Anderson, David
A6: Clinical Centers - Autism Clinical Center | B6: 460 | C6: C&C - Catering | D6: 69500 | E6: Fundraising - Cultivation Events | F6: 2010 | G6: BAR - Barclays Grant for SCP Trainings | H6: BAR1002 | I6: Badaly, Daryaneh | J6: Badaly, Daryaneh
A7: Clinical Centers - LDC Clinical Center | B7: 430 | C7: C&C - Conference Registration Fees Domestic | D7: 69900 | E7: Fundraising - Annual Benefit 2023 | F7: 2103 | G7: Briger Foundation | H7: BRI1001 | I7: Bancroft, Alexis Branca | J7: Bancroft, Alexis Branca
A8: Clinical Centers - Mood Clinical Center | B8: 450 | C8: C&C - Conference Registration Fees Foreign | D8: 69910 | E8: Fundraising - Annual Benefit 2024 | F8: 2104 | G8: CAS - California State - NGDT | H8: CAS1002 - A | I8: Bellantuono, Alessandro | J8: Bellantuono, Alessandro
A9: Clinical Centers - PsyPharm Clinical Center | B9: 440 | C9: C&C - Entertainment | D9: 69550 | E9: Fundraising - Bay Area Golf Tournament 2023 | F9: 2223 | G9: CAS - California State - Resilient Parenting Videos | H9: CAS1002 - B | I9: Benson, William W. | J9: Benson, William W.
A10: Clinical Training | B10: 805 | C10: C&C - Furniture and Equipment Rental | D10: 69520 | E10: Fundraising - Bay Area Golf Tournament 2024 | F10: 2224 | G10: CAS California State Early Talents Program 2022 | H10: CAS1003 | I10: Bernstein, Heather | J10: Bernstein, Heather
A11: Development | B11: 210 | C11: C&C - Materials | D11: 69560 | E11: Fundraising - Fall Luncheon Event 2023 | F11: 2243 | G11: DOE New York City Council (7.1.22-6.30.23) | H11: DOE1005 | I11: Best, Cheryl Kayleen | J11: Best, Cheryl Kayleen
A12: Facilities | B12: 160 | C12: C&C - Other | D12: 69580 | E12: Fundraising - Fall Luncheon Event 2024 | F12: 2244 | G12: DOE NYC City Council DOE 2024 School Year | H12: DOE1006 | I12: Boorady, Roy | J12: Boorady, Roy
A13: Finance | B13: 120 | C13: C&C - Venue Costs | D13: 69510 | E13: Fundraising - Spring Luncheon Event 2023 | F13: 2263 | G13: GOOGLE Online Abuse Research Grant | H13: GGL1001 | I13: Breidenstine, Angela Sue | J13: Breidenstine, Angela Sue
A14: Global Center | B14: 820 | C14: Cards, Gifts and Flowers | D14: 65040 | E14: Fundraising - Spring Luncheon Event 2024 | F14: 2264 | G14: Google Webinar Grant | H14: GGL1002 | I14: Bubrick, Jerome | J14: Bubrick, Jerome
A15: Human Resources | B15: 130 | C15: Employee Lounge and Pantry Supplies | D15: 65030 | E15: Fundraising - Annual Report | F15: 2281 | G15: Google Kids and Family Project | H15: GGL1003 | I15: Burgos, Ramon Luis | J15: Burgos, Ramon Luis
A16: IT | B16: 150 | C16: Employee Training | D16: 51190 | E16: Fundraising - Case for Support | F16: 2282 | G16: GRA - Gray Foundation | H16: GRA1001 | I16: Chase, Lindsey Giller | J16: Chase, Lindsey Giller
A17: MarComms - Communications | B17: 270 | C17: Hardware - End User | D17: 62110 | E17: MarComms - Digital Asset Management System | F17: 2511 | G17: GRA - Gray FDN SCP Grant 12/17/21-11/30/22 | H17: GRA1002 | I17: Coleman, Taina Kwam | J17: Coleman, Taina Kwam
A18: MarComms - Education | B18: 260 | C18: Hardware - End User Desktop | D18: 62115 | E18: MarComms - CMI Weekly Newsletter (x50) | F18: 2512 | G18: Kenrose Kitchen Table Training Expansion 12/1/22-12/1/23 | H18: KEN1003 | I18: Congress, Susanne Elizabeth | J18: Congress, Susanne Elizabeth
A19: Operations | B19: 140 | C19: Hardware - Network Infrastructure | D19: 62100 | E19: MarComms - Social Media Posts and Facebook Like Campaign | F19: 2513 | G19: Kenrose Kitchen Table Training Expansion 1/1/24-12/31/24 | H19: KEN1004 | I19: Cooperman, Alana Lauren | J19: Cooperman, Alana Lauren
A20: President's Office | B20: 110 | C20: Hardware - Server Equipment & Supplies | D20: 62105 | E20: MarComms - Web Dev and SEO (Lucid Circus) | F20: 2514 | G20: LRO - L. Roberts - Ellen Wiesenthal Teacher Initiative | H20: LRO1001 | I20: Crane, Tess | J20: Crane, Tess
A21: Research - Admin, Operations, Sp Projcts | B21: 305 | C21: Hardware - User Licenses | D21: 62120 | E21: MarComms - HSCM List Cost | F21: 2515 | G21: Morbid Podcast | H21: MBD1001 | I21: Cruger, Matthew | J21: Cruger, Matthew
A22: Research - Autism Research Center | B22: 340 | C22: Hosted Services - Application/ Software | D22: 62020 | E22: MarComms - CMI/HSK Origin Video | F22: 2526 | G22: Macy's SCP Grant - West Coast July 2024 | H22: MCY1001 | I22: Dewey, Angela Marie | J22: Dewey, Angela Marie
A23: Research - Center for Data Analytics, Innov, Rigor | B23: 350 | C23: Hosted Services - Compute/Storage services | D23: 62000 | E23: MarComms - Project YouTube | F23: 2527 | G23: MET MetLife Family Resource Center 2023 | H23: MET1001 | I23: Domingues, Janine | J23: Domingues, Janine
A24: Research - Center for Integrative Dev Neuroscience | B24: 310 | C24: Hosted Services - Other | D24: 62040 | E24: MarComms - Science Story Videos: 4 Teams + HBN (x5) | F24: 2528 | G24: MSF - Morgan Stanley Fdn - Digital Parenting Resource Grant | H24: MSF1001 | I24: Duarte, Jeincy | J24: Duarte, Jeincy
A25: Research - Center for Product Development | B25: 330 | C25: Hosted Services - User Licenses | D25: 62030 | E25: MarComms - PR Activity (Sunshine Sachs) | F25: 2551 | G25: MSF - Morgan Stanley Fdn Re-Emergence Initiative | H25: MSF1004 | I25: Dyson, Margaret W. | J25: Dyson, Margaret W.
A26: Research - Healthy Brain Network (HBN) / NGDT | B26: 320 | C26: Internet & Wi-Fi | D26: 62200 | E26: MarComms - Global Citizen Now Event | F26: 2552 | G26: MSF - Morgan Stanley Fdn - Problematic Internet Use Study II 2022 | H26: MSF1005 | I26: Eldridge, Morgan A. | J26: Eldridge, Morgan A.
A27: Research - Strategic Data Initiatives | B27: 355 | C27: Lab and Instructional Supplies | D27: 66020 | E27: MarComms - PR Activity - California (Donna Glass) | F27: 2553 | G27: MSF - Morgan Stanley Fdn - DEI Grant 2022 | H27: MSF1006 | I27: Emanuele, Jill | J27: Emanuele, Jill
A28: Research - Training and Career Dev Inits | B28: 360 | C28: Office Equipment Rental | D28: 65005 | E28: MarComms - Branded Resource Packages (clinical/dev outreach) | F28: 2576 | G28: MSF - Morgan Stanley Fdn - Steve Fund Lit. Review 2024 | H28: MSF1007 | I28: Enenbach, Michael | J28: Enenbach, Michael
A29: SCP - Direct Service - CA | B29: 535 | C29: Office Supplies | D29: 65000 | E29: MarComms - NY Clinician School Talks x120 | F29: 2577 | G29: NIH - Columbia Univ. - Predicting Heterogeneous - NIMH | H29: NIH1001 | I29: Espejo, Karol B. | J29: Espejo, Karol B.
A30: SCP - Direct Service - NY | B30: 530 | C30: On Premise - Application/Software | D30: 62050 | E30: MarComms - Clinician/Patient Photography | F30: 2578 | G30: NIH - Signatures - NIMH | H30: NIH1002 | I30: Esperanza, Pamelynn | J30: Esperanza, Pamelynn
A31: SCP - General Core | B31: 510 | C31: Other Insurance | D31: 64550 | E31: MarComms - Clinician Videos x30 - 45 | F31: 2579 | G31: NIH - NKI - Defining Neuronal Circuits NIMH (Subward) | H31: NIH1004 | I31: Ferrigno, Matthew A. | J31: Ferrigno, Matthew A.
A32: SCP - Professional Training - CA | B32: 545 | C32: Other Office Expense | D32: 65055 | E32: MarComms - Patient Story/Testimonial Videos | F32: 2580 | G32: NIH - CPAC R24MH114806 | H32: NIH1005 | I32: Friedlander, David | J32: Friedlander, David
A33: SCP - Professional Training - NY | B33: 540 | C33: Participant Payments & Reimbursements | D33: 66030 | E33: MarComms - PSA Distribution | F33: 2601 | G33: NIH - Neurobiology/Dynamics - NIMH (Conte -sub with NKI) | H33: NIH1007 | I33: Ganz, Rachel Emily | J33: Ganz, Rachel Emily
A34: SCP - Project UROK | B34: 520 | C34: Postage, Shipping and Mailing Service | D34: 65010 | E34: MarComms - Collateral (Biz Cards, Profile Photo, etc.) | F34: 2602 | G34: NIH - Univ. of Connecticut - Optimal Outcomes - NIMH | H34: NIH1009 | I34: Greenspan, Amanda N | J34: Greenspan, Amanda N
C35: Printing and Copying | D35: 65015 | E35: MarComms - HSK Talks and Presentations (x12) | F35: 2603 | G35: NIH - Univ. of Penn - Reproducible Imaging-Based - NIMH | H35: NIH1010 | I35: Gudino, Omar Gabriel | J35: Gudino, Omar Gabriel
C36: Professional Liability Insurance | D36: 64535 | E36: MarComms - Misc. Research Projects (Ipsos, etc.) | F36: 2604 | G36: NIH - Univ. of Minnesota - Open Software - NIMH | H36: NIH1012 | I36: Guterman, Leah | J36: Guterman, Leah
C37: Professional Memberships and Organization Dues | D37: 65045 | E37: MarComms - Mental Health Month (May) Campaign | F37: 2605 | G37: NIH - Univ. of Connecticut - GraphoLearn - NICHD | H37: NIH1014 | I37: Guttentag, Sara | J37: Guttentag, Sara
C38: Program Supplies | D38: 66000 | E38: MarComms - Children Mental's Health Report | F38: 2606 | G38: NIH - Brain Network Supplement - NIMH/NIDA contract | H38: NIH1015 | I38: Hamel, Jessica | J38: Hamel, Jessica
C39: Publications, Books, Licenses | D39: 66010 | E39: MarComms - Editorial Freelance Writing | F39: 2607 | G39: NIH - UCSD Brain Initiative -FY21 | H39: NIH1016 | I39: Heyman, Michelle Rose | J39: Heyman, Michelle Rose
C40: Relocation Expenses | D40: 51185 | E40: MarComms - Spanish Freelance Translation/Editing budget | F40: 2608 | G40: NIH - BRAIN - NIMH | H40: NIH1017 | I40: Ho, Jennifer | J40: Ho, Jennifer
...

Sheet Travel Reimb Form
I1: EXPENSE BREAKDOWN SHEET (TRAVEL)
I2: Attach to Form EXP2000
D3: Use this form to report and request reimbursement for expenses incurred during business travel. All travel expenses must conform to the CMI's Expense Reimbursement Policy . In the case of grants or contracts, Sponsor's regulations or contract terms must also be followed. For per diem amount applicable to foreign travel charged to grants or contracts, refer to the government website (www.state.gov/travel). *For current mileage rate, refer to the IRS website (http://www.irs.gov/taxpros/article/0,,id=156624,00.html)
A5: PAYEE'S FULL NAME (First, Middle Initial, Last) | F5: DEPARTMENT | I5: TELEPHONE NUMBER
A8: INCLUSIVE DATES OF TRAVEL | C8: BUSINESS PURPOSE OF TRAVEL
A9: DEPARTURE
A10: RETURN
A12: EXPENSE DETAILS
A13: DATE | B13: HOTEL | C13: AIR/BUS/RAIL | D13: PERSONAL CAR/*TOLLS | E13: CAR RENTAL | F13: PARKING | G13: CAR SERVICE/TAXI | H13: TELEPHONE/FAX/INTERNET | I13: SUBTOTAL
I14: =SUM(B14:H14) -> 0
I15: =SUM(B15:H15) -> 0
I16: =SUM(B16:H16) -> 0
I17: =SUM(B17:H17) -> 0
I18: =SUM(B18:H18) -> 0
I19: =SUM(B19:H19) -> 0
I20: =SUM(B20:H20) -> 0
I21: =SUM(B21:H21) -> 0
A22: SUBTOTAL (GENERAL EXPENSES) | B22: =SUM(B14:B21) -> 0 | C22: =SUM(C14:C21) -> 0 | D22: =SUM(D14:D21) -> 0 | E22: =SUM(E14:E21) -> 0 | F22: =SUM(F14:F21) -> 0 | G22: =SUM(G14:G21) -> 0 | H22: =SUM(H14:H21) -> 0 | I22: =SUM(I14:I21) -> 0 | J22: (A)
A24: MEALS DURING TRAVEL AND OTHER EXPENSES: Use this section for meal expenses incurred during travel. Meal expenses not related to travel should be reported on Form EXP2000.
A25: DATE | B25: BREAKFAST | C25: LUNCH | D25: DINNER | E25: SUBTOTAL | F25: OTHER (DESCRIPTION) | I25: OTHER (AMOUNT)
E26: =SUM(B26:D26) -> 0
E27: =SUM(B27:D27) -> 0
E28: =SUM(B28:D28) -> 0
E29: =SUM(B29:D29) -> 0
E30: =SUM(B30:D30) -> 0
E31: =SUM(B31:D31) -> 0
E32: =SUM(B32:D32) -> 0
E33: =SUM(B33:D33) -> 0
A34: SUBTOTAL (MEALS) | B34: =SUM(B26:B33) -> 0 | C34: =SUM(C26:C33) -> 0 | D34: =SUM(D26:D33) -> 0 | E34: =SUM(E26:E33) -> 0 | F34: SUBTOTAL (OTHER EXPENSES INCURRED DURING TRAVEL) | I34: =SUM(I26:I33) -> 0 | J34: (B)
E35: (C)
G36: TOTAL TRAVEL EXPENSES (A + B + C) | I36: =I22+E34+I34 -> 0

Sheet Missing Doc Form
A5: MISSING/INADEQUATE DOCUMENTATION FORM
A7: Use this form when you are requesting reimbursement from the CMI for expenses that are not supported by original receipts or other documentation.
A8: This form is not required for miscellaneous expenses under $25. When expenses are for meals, however, receipts are required even when the amount is under $25. Use this form when requesting reimbursement for meals with missing or inadequate documentation, even when the amount is under $25.
A9: Attach completed form to your Expense Reimbursement Form, along with other documentation you are providing in lieu of original receipts/other appropriate documentation.
A10: For guidance on reimbursement of expenses, refer to the Expense Reimbursement Policy.
A13: DATE
A15: NAME | B15: DEPARTMENT | C15: TELEPHONE NUMBER
A18: DOCUMENTATION MISSING
A19: (Check one only. Use one form for each expense with missing or inadequate documentation.)
A22: BUSINESS MEALS (TRAVEL) | B22: GROUND TRANSPORTATION | C22: OTHER (SPECIFY):
A24: BUSINESS MEALS (NONTRAVEL) | B24: PARKING, TOLL, ETC.
C26: ____________________________________________
A31: SUPPORTING DOCUMENTATION PROVIDED IN LIEU OF MISSING RECEIPT OR APPROPRIATE DOCUMENTATION:
A35: ______________________________________________________________________________________________________________
A39: ______________________________________________________________________________________________________________
A43: ______________________________________________________________________________________________________________
A47: ______________________________________________________________________________________________________________
A51: ______________________________________________________________________________________________________________
A56: STATEMENT:
A57: I, the Payee, certify that the original receipt/s for the expense/s reported on the Expense Reimbursement Form and/or Expense Breakdown Sheet (Travel) was/were lost and a copy could not be obtained from the vendor. I certify that these expenses for which I am seeking reimbursement from the CMI will not be submitted for reimbursement to any other organization or agency. I also certify that the expenses do not include federal “unallowable costs”.
A58: __________________________________________________
A60: PAYEE SIGNATURE

Sheet CMI Staff Exp Reimb POLICY
A3: Expense Reimbursement Policy
A6: Purpose
A7: The Child Mind Institute (CMI) recognizes that board members, officers and employees may be required to travel or incur other expenses to further the mission of this nonprofit organization. The purpose of this policy is to ensure that (a) adequate cost controls are in place, (b) travel and other expenditures are appropriate, and (c) to provide a uniform and consistent approach for the timely reimbursement of authorized expenses incurred by personnel. It is CMI’s policy to reimburse only reasonable and necessary expenses actually incurred by personnel.
A9: When incurring business expenses, CMI expects personnel to:
A10: · Exercise discretion and good business judgment with respect to those expenses.
A11: · Be cost conscious and spend CMI’s funds as carefully and judiciously as the individual would spend his or her own funds.
A12: · Report expenses, supported by required documentation, as they were actually spent.
A14: Expense Reporting
A15: Expense Report – Expenses will not be reimbursed unless the individual requesting reimbursement submits a written Expense Reimbursement Form, which must include:
A16: · The individual’s name.
A17: · If reimbursement for travel is requested, the date, origin, destination and purpose of the trip.
A18: · The name and affiliation of all people for whom expenses are claimed (i.e., people on whom money is spent in order to conduct CMI’s business).
... A84: · Expenses for spouses, friends or relatives. If a spouse, friend or relative accompanies personnel on a trip, it is the responsibility of the personnel to determine any added cost for double occupancy and related expenses and to make the appropriate adjustment in the reimbursement request.

Sheet NON-CMI STAFF Exp Reimb POLICY
A1: EXTERNAL EXPENSE REIMBURSEMENT POLICY
A3: Purpose
A4: The purpose of this policy is to specify the reimbursable expense items for individuals who are not employed by the Child Mind Institute (CMI) and to outline the process for receiving reimbursement from CMI.
A6: Allowable Expenses
A7: CMI will only reimburse expenses directly related to visits to the CMI and meetings with CMI clinicians. These expenses include:
A8: · Transportation to and from New York City
A9: · Transportation to and from CMI and affiliated facilities
A10: · Lodging
A11: · Breakfast and lunch if these meals are not provided by the CMI or affiliated institutions. Breakfast can be reimbursed up to $10.
A13: Unallowable Expenses
A14: The CMI will not reimburse the following items:
A15: · Transportation not associated with the visit to CMI or affiliated facilities
... A36: Expenses incurred in the conduct of CMI business generally should be accounted for within 30 days after the date of expenditure, completion of event, or return from a trip.
